Workbook

Sheet Actual_Revenue
A1: State | B1: Actual Revenue 2021 | C1: Actual Revenue 2022 | D1: Actual Revenue 2023 | E1: Actual Revenue 2024
A2: ABIA | B2: 1.2400879e+11 | C2: 1.4763773e+11 | D2: 1.6830199e+11 | E2: 3.7329982e+11
A3: ADAMAWA | B3: 9.4208536e+10 | C3: 1.0972295e+11 | D3: 1.609227e+11 | E3: 2.8847722e+11
A4: AKWA IBOM | B4: 378570288000 | C4: 444288683000 | D4: 483513096000 | E4: 1070449162000
A5: ANAMBRA | B5: 1.138736e+11 | C5: 1.3358395e+11 | D5: 1.7328708e+11 | E5: 3.5686764e+11
A6: BAUCHI | B6: 9.4882291e+10 | C6: 1.5419782e+11 | D6: 2.1978575e+11 | E6: 3.6163287e+11
A7: BAYELSA | B7: 2.4045623e+11 | C7: 3.6537343e+11 | D7: 4.6726154e+11 | E7: 9.972269e+11
A8: BENUE | B8: 8.9565263e+10 | C8: 1.1361915e+11 | D8: 1.4798038e+11 | E8: 3.2764913e+11
A9: BORNO | B9: 137956401838 | C9: 169773847058 | D9: 221247393912 | E9: 462727048082
A10: CROSS RIVER | B10: 1.4519995e+11 | C10: 1.3757058e+11 | D10: 1.7480936e+11 | E10: 5.3273837e+11
A11: DELTA | B11: 3.7567565e+11 | C11: 7.0202072e+11 | D11: 8.011816e+11 | E11: 1.3921658e+12
A12: EBONYI | B12: 1.0210334e+11 | C12: 1.480545e+11 | D12: 1.3195673e+11 | E12: 2.4850393e+11
A13: EDO | B13: 1.8117406e+11 | C13: 2.0732307e+11 | D13: 2.6890719e+11 | E13: 4.8294301e+11
... A37: ZAMFARA | B37: 9.4451446e+10 | C37: 134830832320 | D37: 1.5804861e+11 | E37: 3.2013241e+11
A38: TOTAL | B38: =SUM(B2:B37) -> 6.3290259e+12 | C38: =SUM(C2:C37) -> 8.1681145e+12 | D38: =SUM(D2:D37) -> 1.0748803e+13 | E38: =SUM(E2:E37) -> 1.794883e+13

Sheet Actual_Expenditure 
A1: State | B1: Actual Expenditure 2021 | C1: Actual Expenditure 2022 | D1: Actual Expenditure 2023 | E1: Actual Expenditure 2024
A2: ABIA | B2: 1.1866663e+11 | C2: 1.5740627e+11 | D2: 1.4517256e+11 | E2: 3.2525081e+11
A3: ADAMAWA | B3: 1.0016774e+11 | C3: 1.0837326e+11 | D3: 1.6196458e+11 | E3: 2.6785622e+11
A4: AKWA IBOM | B4: 360551256000 | C4: 435425927000 | D4: 442227039000 | E4: 816437531000
A5: ANAMBRA | B5: 1.2276795e+11 | C5: 1.2141078e+11 | D5: 1.62552e+11 | E5: 2.956914e+11
A6: BAUCHI | B6: 1.2652328e+11 | C6: 1.5200461e+11 | D6: 1.6047909e+11 | E6: 3.2014183e+11
A7: BAYELSA | B7: 2.3831615e+11 | C7: 3.1190823e+11 | D7: 4.9234536e+11 | E7: 8.1840462e+11
A8: BENUE | B8: 8.9565263e+10 | C8: 1.1502325e+11 | D8: 1.2126922e+11 | E8: 2.7234744e+11
A9: BORNO | B9: 149563888672 | C9: 159272306933 | D9: 199592937267 | E9: 439496194881
A10: CROSS RIVER | B10: 1.47033e+11 | C10: 1.3954986e+11 | D10: 1.3643875e+11 | E10: 4.3237733e+11
A11: DELTA | B11: 3.8220568e+11 | C11: 5.8552242e+11 | D11: 5.7950299e+11 | E11: 7.333493e+11
A12: EBONYI | B12: 1.0906411e+11 | C12: 1.2277858e+11 | D12: 1.3087182e+11 | E12: 2.271307e+11
A13: EDO | B13: 1.779424e+11 | C13: 2.0712304e+11 | D13: 2.7238261e+11 | E13: 4.5856955e+11
... A37: ZAMFARA | B37: 9.1980331e+10 | C37: 1.3402053e+11 | D37: 1.1899879e+11 | E37: 2.5844367e+11
A38: TOTAL: | B38: =SUM(B2:B37) -> 6.4351503e+12 | C38: =SUM(C2:C37) -> 7.9406841e+12 | D38: =SUM(D2:D37) -> 9.3433619e+12 | E38: =SUM(E2:E37) -> 1.542537e+13

Sheet Total_Budget_Revenue 
A1: State | B1: Total Revenue 2023 | C1: Total Revenue 2024 | D1: Total Revenue 2025 | E1: Total Revenue 2026
A2: ABIA | B2: 160517504300 | C2: 501705486709 | D2: 728873500618 | E2: 999466023300
A3: ADAMAWA | B3: 175019054060 | C3: 225893690626 | D3: 486218047600 | E3: 5.3060526e+11
A4: AKWA IBOM | B4: 660000000000 | C4: 789970759990 | D4: 855000000000 | E4: 1363571856630
A5: ANAMBRA | B5: 1.7039469e+11 | C5: 3.7995726e+11 | D5: 5.4199185e+11 | E5: 7.2137449e+11
A6: BAUCHI | B6: 1.9264381e+11 | C6: 2.8574672e+11 | D6: 4.5010023e+11 | E6: 8.6506789e+11
A7: BAYELSA | B7: 3.7716e+11 | C7: 475818632374 | D7: 6.8537317e+11 | E7: 1.0018713e+12
A8: BENUE | B8: 1.7975009e+11 | C8: 2.257274e+11 | D8: 5.5011299e+11 | E8: 6.9501124e+11
A9: BORNO | B9: 234031950000 | C9: 353732146000 | D9: 590857950000 | E9: 861332179000
A10: CROSS RIVER | B10: 3.2432784e+11 | C10: 295635531978 | D10: 533523915716 | E10: 9.5362405e+11
A11: DELTA | B11: 561636910991 | C11: 7.1497931e+11 | D11: 9.2607882e+11 | E11: 1.6998812e+12
A12: EBONYI | B12: 134398280640 | C12: 196127918907 | D12: 429978000000 | E12: 8.7680712e+11
A13: EDO | B13: 3.1635001e+11 | C13: 3.3282597e+11 | D13: 6.6522006e+11 | E13: 919850000000
... A37: ZAMFARA | B37: 1.8487212e+11 | C37: 426563671000 | D37: 546014575000 | E37: 871337000000
A38: TOTAL | B38: =SUM(B2:B37) -> 1.0484633e+13 | C38: =SUM(C2:C37) -> 1.5668697e+13 | D38: =SUM(D2:D37) -> 2.5379563e+13 | E38: =SUM(E2:E37) -> 3.4408443e+13

Sheet Total_Budget_Expenditure
A1: State | B1: Total Expenditure 2023 | C1: Total Expenditure 2024 | D1: Total Expenditure 2025 | E1: Total Expenditure 2026
A2: ABIA | B2: 160517504300 | C2: 567240095972 | D2: 750282200000 | E2: 1.0162281e+12
A3: ADAMAWA | B3: 175019054060 | C3: 225893690626 | D3: 486218047600 | E3: 583331380496
A4: AKWA IBOM | B4: 700000000000 | C4: 849970759990 | D4: 955000000000 | E4: 1584271856630
A5: ANAMBRA | B5: 2.6039469e+11 | C5: 4.1013223e+11 | D5: 6.0699185e+11 | E5: 7.6637449e+11
A6: BAUCHI | B6: 2.0264156e+11 | C6: 3.0021971e+11 | D6: 4.6708525e+11 | E6: 8.7705291e+11
A7: BAYELSA | B7: 3.8937158e+11 | C7: 489443632374 | D7: 6.9957317e+11 | E7: 1.0160713e+12
A8: BENUE | B8: 1.7975009e+11 | C8: 2.257274e+11 | D8: 5.5011299e+11 | E8: 6.9501124e+11
A9: BORNO | B9: 235331950000 | C9: 358732146000 | D9: 615857950000 | E9: 892448411000
A10: CROSS RIVER | B10: 3.2823524e+11 | C10: 2.9698553e+11 | D10: 5.3852392e+11 | E10: 9.6162405e+11
A11: DELTA | B11: 5.7163691e+11 | C11: 7.2497931e+11 | D11: 9.7922882e+11 | E11: 1.7298812e+12
A12: EBONYI | B12: 139398280640 | C12: 202127918907 | D12: 444978000000 | E12: 8.8580712e+11
A13: EDO | B13: 3.2135001e+11 | C13: 3.4282597e+11 | D13: 6.7522006e+11 | E13: 939850000000
... A37: ZAMFARA | B37: 1.8487212e+11 | C37: 426563671000 | D37: 546014575000 | E37: 8.71337e+11
A38: TOTAL | B38: =SUM(B2:B37) -> 1.0938415e+13 | C38: =SUM(C2:C37) -> 1.6152731e+13 | D38: =SUM(D2:D37) -> 2.6616794e+13 | E38: =SUM(E2:E37) -> 3.5945909e+13

Sheet Total_Expen_Original_and_Actual
B1: Original | E1: Actual
A2: Year | B2: Revenue (not including opening balance) | C2: Expenditure | E2: Revenue (not including opening balance) | F2: Expenditure
A3: 2018 | B3: 9.2252927e+12 | C3: 9.2861698e+12 | E3: 5.3452318e+12 | F3: 5.2653292e+12
A4: 2019 | B4: 9.2137459e+12 | C4: 9.3419536e+12 | E4: 5.400775e+12 | F4: 5.211974e+12
A5: 2020 | B5: 9.2661461e+12 | C5: 9.4425034e+12 | E5: 5.0934416e+12 | F5: 4.9620967e+12
A6: 2021 | B6: 7.7702708e+12 | C6: 8.2630299e+12 | E6: 6.3290259e+12 | F6: 6.4351503e+12
A7: 2022 | B7: 9.4811204e+12 | C7: 9.810486e+12 | E7: =Actual_Revenue!C38 -> 8.1681145e+12 | F7: ='Actual_Expenditure '!C38 -> 7.9406841e+12
A8: 2023 | B8: 1.0484633e+13 | C8: 10938414853846 | E8: =Actual_Revenue!D38 -> 1.0748803e+13 | F8: ='Actual_Expenditure '!D38 -> 9.3433619e+12
A9: 2024 | B9: ='Total_Budget_Revenue '!C38 -> 1.5668697e+13 | C9: =Total_Budget_Expenditure!C38 -> 1.6152731e+13 | E9: =Actual_Revenue!E38 -> 1.794883e+13 | F9: ='Actual_Expenditure '!E38 -> 1.542537e+13
A10: 2025 | B10: ='Total_Budget_Revenue '!D38 -> 2.5379563e+13 | C10: =Total_Budget_Expenditure!D38 -> 2.6616794e+13
A11: 2026 | B11: ='Total_Budget_Revenue '!E38 -> 3.4408443e+13 | C11: =Total_Budget_Expenditure!E38 -> 3.5945909e+13

Sheet Geo_Pol_Original_Exp
A1: South-West | E1: North-East
A2: S/No | B2: State | C2: Original Budget 2026 | E2: S/No | F2: State | G2: Original Budget 2026
A3: 1 | B3: Ekiti | C3: =Total_Budget_Expenditure!E14 -> 4.1557207e+11 | E3: 1 | F3: Adamawa | G3: =Total_Budget_Expenditure!E3 -> 583331380496
A4: 2 | B4: Lagos | C4: =Total_Budget_Expenditure!E25 -> 4.4445098e+12 | E4: 2 | F4: Bauchi | G4: =Total_Budget_Expenditure!E6 -> 8.7705291e+11
A5: 3 | B5: Ondo | C5: =Total_Budget_Expenditure!E29 -> 524410590939 | E5: 3 | F5: Borno | G5: =Total_Budget_Expenditure!E9 -> 892448411000
A6: 4 | B6: Osun | C6: =Total_Budget_Expenditure!E30 -> 723454988670 | E6: 4 | F6: Gombe | G6: =Total_Budget_Expenditure!E16 -> 617956083000
A7: 5 | B7: Oyo | C7: =Total_Budget_Expenditure!E31 -> 8.9208507e+11 | E7: 5 | F7: Taraba | G7: =Total_Budget_Expenditure!E35 -> 653631700000
A8: 6 | B8: Ogun | C8: =Total_Budget_Expenditure!E28 -> 1.668998e+12 | E8: 6 | F8: Yobe | G8: =Total_Budget_Expenditure!E36 -> 515532000000
A12: North-West | E12: South-South
A13: S/No | B13: State | C13: Original Budget 2026 | E13: S/No | F13: State | G13: Original Budget 2026
A14: 1 | B14: Jigawa | C14: =Total_Budget_Expenditure!E18 -> 901841000000 | E14: 1 | F14: Akwa Ibom | G14: =Total_Budget_Expenditure!E4 -> 1584271856630
A15: 2 | B15: Kano | C15: =Total_Budget_Expenditure!E20 -> 1.4778297e+12 | E15: 2 | F15: Bayelsa | G15: =Total_Budget_Expenditure!E7 -> 1.0160713e+12
A16: 3 | B16: Katsina | C16: =Total_Budget_Expenditure!E21 -> 8.9786508e+11 | E16: 3 | F16: Cross River | G16: =Total_Budget_Expenditure!E10 -> 9.6162405e+11
A17: 4 | B17: Kaduna | C17: =Total_Budget_Expenditure!E19 -> 9.8591514e+11 | E17: 4 | F17: Delta | G17: =Total_Budget_Expenditure!E11 -> 1.7298812e+12
A18: 5 | B18: Kebbi | C18: =Total_Budget_Expenditure!E22 -> 6.4293082e+11 | E18: 5 | F18: Edo | G18: =Total_Budget_Expenditure!E13 -> 939850000000
A19: 6 | B19: Sokoto | C19: =Total_Budget_Expenditure!E34 -> 7.5870053e+11 | E19: 6 | F19: Rivers | G19: =Total_Budget_Expenditure!E33 -> 0
A20: 7 | B20: Zamfara | C20: =Total_Budget_Expenditure!E37 -> 8.71337e+11
A24: South-East | E24: North-Central
A25: S/No | B25: State | C25: Original Budget 2026 | E25: S/No | F25: State | G25: Original Budget 2026
A26: 1 | B26: Abia | C26: =Total_Budget_Expenditure!E2 -> 1.0162281e+12 | E26: 1 | F26: Benue | G26: =Total_Budget_Expenditure!E8 -> 6.9501124e+11
A27: 2 | B27: Imo | C27: =Total_Budget_Expenditure!E17 -> 1.4742209e+12 | E27: 2 | F27: Kogi | G27: =Total_Budget_Expenditure!E23 -> 820490585443
A28: 3 | B28: Ebonyi | C28: =Total_Budget_Expenditure!E12 -> 8.8580712e+11 | E28: 3 | F28: Kwara | G28: =Total_Budget_Expenditure!E24 -> 6.5659556e+11
A29: 4 | B29: Enugu | C29: =Total_Budget_Expenditure!E15 -> 1617397465000 | E29: 4 | F29: Nasarawa | G29: =Total_Budget_Expenditure!E26 -> 5.451821e+11
A30: 5 | B30: Anambra | C30: =Total_Budget_Expenditure!E5 -> 7.6637449e+11 | E30: 5 | F30: Niger | G30: =Total_Budget_Expenditure!E27 -> 1.0739913e+12
E31: 6 | F31: Plateau | G31: =Total_Budget_Expenditure!E32 -> 8.1750969e+11

Sheet Expenditure_by_Function
A2: 2023 Budget
A3: S/No | B3: Description | C3: Recurrent | D3: Capital | E3: Total
A4: 1 | B4: General Public Service | C4: 2.2730709e+12 | D4: 1.2573805e+12 | E4: =SUM(C4:D4) -> 3.5304515e+12
A5: 2 | B5: Public Order & Safety | C5: 2.4792238e+11 | D5: 1.432116e+11 | E5: =SUM(C5:D5) -> 3.9113398e+11
A6: 3 | B6: Economic Affairs | C6: 4.2903663e+11 | D6: 2.2371787e+12 | E6: =SUM(C6:D6) -> 2.6662153e+12
A7: 4 | B7: Environmental Protection | C7: 6.2464039e+10 | D7: 1.8364949e+11 | E7: =SUM(C7:D7) -> 2.4611353e+11
A8: 5 | B8: Housing and Community Ammenities | C8: 2.7115042e+11 | D8: 5.5108015e+11 | E8: =SUM(C8:D8) -> 8.2223057e+11
A9: 6 | B9: Health | C9: 3.7380458e+11 | D9: 4.6124611e+11 | E9: =SUM(C9:D9) -> 835050691121
A10: 7 | B10: Recreation and Culture | C10: 1.2096194e+11 | D10: 1.0886782e+11 | E10: =SUM(C10:D10) -> 2.2982976e+11
A11: 8 | B11: Education | C11: 9.291335e+11 | D11: 6.8503698e+11 | E11: =SUM(C11:D11) -> 1.6141705e+12
A12: 9 | B12: Social Protection | C12: 4.5754114e+11 | D12: 1.4522387e+11 | E12: =SUM(C12:D12) -> 6.02765e+11
E14: Total
C15: =SUM(C4:C12) -> 5.1650856e+12 | D15: =SUM(D4:D12) -> 5.7728752e+12 | E15: =SUM(C15:D15) -> 1.0937961e+13
A18: 2024 Budget
A19: S/No | B19: Description | C19: Recurrent | D19: Capital | E19: Total
A20: 1 | B20: General Public Service | C20: 2.6406549e+12 | D20: 2.1105452e+12 | E20: =SUM(C20:D20) -> 4.7512e+12
A21: 2 | B21: Public Order & Safety | C21: 3.5617462e+11 | D21: 2.47744e+11 | E21: =SUM(C21:D21) -> 6.0391862e+11
A22: 3 | B22: Economic Affairs | C22: 2.8697572e+11 | D22: 3.9153523e+12 | E22: =SUM(C22:D22) -> 4.202328e+12
A23: 4 | B23: Environmental Protection | C23: 8.0020163e+10 | D23: 2.5646761e+11 | E23: =SUM(C23:D23) -> 3.3648778e+11
A24: 5 | B24: Housing and Community Ammenities | C24: 1.8076164e+11 | D24: 9.467116e+11 | E24: =SUM(C24:D24) -> 1.1274732e+12
A25: 6 | B25: Health | C25: 5.6975102e+11 | D25: 7.9032871e+11 | E25: =SUM(C25:D25) -> 1.3600797e+12
A26: 7 | B26: Recreation and Culture | C26: 1.8374806e+11 | D26: 2.0805026e+11 | E26: =SUM(C26:D26) -> 3.9179832e+11
A27: 8 | B27: Education | C27: 1.1728909e+12 | D27: 1.2626354e+12 | E27: =SUM(C27:D27) -> 2.4355263e+12
A28: 9 | B28: Social Protection | C28: 7.4149813e+11 | D28: 2.0242062e+11 | E28: =SUM(C28:D28) -> 9.4391875e+11
E30: Total
C31: =SUM(C20:C28) -> 6.2124752e+12 | D31: =SUM(D20:D28) -> 9.9402556e+12 | E31: =SUM(C31:D31) -> 1.6152731e+13
A33: 2025 Budget
A34: S/No | B34: Description | C34: Recurrent | D34: Capital | E34: Total
A35: 1 | B35: General Public Service | C35: 3.6477896e+12 | D35: 2.2839867e+12 | E35: =SUM(C35:D35) -> 5.9317763e+12
A36: 2 | B36: Public Order & Safety | C36: 5.3125515e+11 | D36: 4.7315803e+11 | E36: =SUM(C36:D36) -> 1.0044132e+12
A37: 3 | B37: Economic Affairs | C37: 4.5230625e+11 | D37: 8.2922495e+12 | E37: =SUM(C37:D37) -> 8.7445557e+12
A38: 4 | B38: Environmental Protection | C38: 1.3607422e+11 | D38: 5.4908103e+11 | E38: =SUM(C38:D38) -> 6.8515525e+11
A39: 5 | B39: Housing and Community Ammenities | C39: 2.5132723e+11 | D39: 1.8027204e+12 | E39: =SUM(C39:D39) -> 2.0540476e+12
A40: 6 | B40: Health | C40: 7.8665812e+11 | D40: 1.5073992e+12 | E40: =SUM(C40:D40) -> 2.2940573e+12
A41: 7 | B41: Recreation and Culture | C41: 2.5517339e+11 | D41: 3.5601416e+11 | E41: =SUM(C41:D41) -> 6.1118754e+11
A42: 8 | B42: Education | C42: 1.6627613e+12 | D42: 2.2351371e+12 | E42: =SUM(C42:D42) -> 3.8978984e+12
A43: 9 | B43: Social Protection | C43: 1.0229227e+12 | D43: 3.7078014e+11 | E43: =SUM(C43:D43) -> 1.3937028e+12
E45: Total
C46: =SUM(C35:C43) -> 8.7462679e+12 | D46: =SUM(D35:D43) -> 1.7870526e+13 | E46: =SUM(C46:D46) -> 2.6616794e+13
A51: 2026 Budget
...

Sheet Expenditure_by_Programme
A2: 2024 Budget (Expenditure By Programme)
A3: S/No | B3: Description | C3: Recurrent | D3: Capital | E3: Total
A4: 1 | B4: Agriculture | C4: 1.1227785e+11 | D4: 4.5256405e+11 | E4: =SUM(C4:D4) -> 5.648419e+11
A5: 2 | B5: Societal Re-orientation | C5: 1.6652665e+11 | D5: 3.7694733e+11 | E5: =SUM(C5:D5) -> 5.4347398e+11
A6: 3 | B6: Poverty Alleviation | C6: 4.6213477e+10 | D6: 1.0132758e+11 | E6: =SUM(C6:D6) -> 1.4754105e+11
A7: 4 | B7: Health | C7: 5.8932849e+11 | D7: 8.6500132e+11 | E7: =SUM(C7:D7) -> 1.4543298e+12
A8: 5 | B8: Education | C8: 1.1509297e+12 | D8: 1.1938913e+12 | E8: =SUM(C8:D8) -> 2.344821e+12
A9: 6 | B9: Housing and Urban Development | C9: 7.1424969e+10 | D9: 5.776396e+11 | E9: =SUM(C9:D9) -> 6.4906457e+11
A10: 7 | B10: Gender | C10: 3.1133483e+10 | D10: 7.67575e+10 | E10: =SUM(C10:D10) -> 1.0789098e+11
A11: 8 | B11: Youth | C11: 6.1734533e+10 | D11: 1.4726738e+11 | E11: =SUM(C11:D11) -> 2.0900191e+11
A12: 9 | B12: Environmental Improvement | C12: 7.7161334e+10 | D12: 1.9580205e+11 | E12: =SUM(C12:D12) -> 2.7296339e+11
A13: 10 | B13: Water Resources and Rural Development | C13: 1.022596e+11 | D13: 3.3435741e+11 | E13: =SUM(C13:D13) -> 4.36617e+11
A14: 11 | B14: Information Communication and Technology | C14: 5.3803312e+10 | D14: 1.1512754e+11 | E14: =SUM(C14:D14) -> 1.6893085e+11
A15: 12 | B15: Growing the Private Sector | C15: 3.9750791e+10 | D15: 1.2052971e+11 | E15: =SUM(C15:D15) -> 1.6028051e+11
... A24: 21 | B24: Oil and Gas Infrastructure | C24: 4.2017052e+09 | D24: 2.9601003e+10 | E24: =SUM(C24:D24) -> 3.3802708e+10
A25: 22 | B25: Solid Minerals
C26: =SUM(C4:C24) -> 6.2124752e+12 | D26: =SUM(D4:D24) -> 9.9402556e+12 | E26: =SUM(C26:D26) -> 1.6152731e+13
A29: 2025 Budget (Expenditure By Programme)
A30: S/No | B30: Description | C30: Recurrent | D30: Capital | E30: Total
A31: 1 | B31: Agriculture | C31: 1.3201407e+11 | D31: 1.5093201e+12 | E31: =SUM(C31:D31) -> 1.6413342e+12
A32: 2 | B32: Societal Re-orientation | C32: 2.3470038e+11 | D32: 255332223969 | E32: =SUM(C32:D32) -> 4.900326e+11
A33: 3 | B33: Poverty Alleviation | C33: 2.4575986e+11 | D33: 2.3208316e+11 | E33: =SUM(C33:D33) -> 4.7784301e+11
A34: 4 | B34: Health | C34: 9.6202294e+11 | D34: 1.5156081e+12 | E34: =SUM(C34:D34) -> 2.477631e+12
A35: 5 | B35: Education | C35: 1.5799691e+12 | D35: 2.2734643e+12 | E35: =SUM(C35:D35) -> 3.8534334e+12
A36: 6 | B36: Housing and Urban Development | C36: 1.1646631e+11 | D36: 1.2749264e+12 | E36: =SUM(C36:D36) -> 1.3913927e+12
A37: 7 | B37: Gender | C37: 3.4910696e+10 | D37: 1.093406e+11 | E37: =SUM(C37:D37) -> 1.442513e+11
A38: 8 | B38: Youth | C38: 8.5346704e+10 | D38: 1.6676545e+11 | E38: =SUM(C38:D38) -> 2.5211216e+11
A39: 9 | B39: Environmental Improvement | C39: 1.2668091e+11 | D39: 3.3556001e+11 | E39: =SUM(C39:D39) -> 4.6224093e+11
A40: 10 | B40: Water Resources and Rural Development | C40: 1.2907378e+11 | D40: 6.1482701e+11 | E40: =SUM(C40:D40) -> 7.439008e+11
A41: 11 | B41: Information Communication and Technology | C41: 7.9699656e+10 | D41: 1.9599023e+11 | E41: =SUM(C41:D41) -> 2.7568989e+11
A42: 12 | B42: Growing the Private Sector | C42: 5.3591945e+10 | D42: 2.3603869e+11 | E42: =SUM(C42:D42) -> 2.8963064e+11
... A52: 22 | B52: Solid Minerals | C52: 3.4575e+08 | D52: 2.3310387e+08 | E52: =SUM(C52:D52) -> 5.7885387e+08
A53: TOTAL: | C53: =SUM(C31:C52) -> 8.7462679e+12 | D53: =SUM(D31:D52) -> 1.7870526e+13 | E53: =SUM(C53:D53) -> 2.6616794e+13
A56: 2026 Budget (Expenditure By Programme)
A57: S/No | B57: Description | C57: Recurrent | D57: Capital | E57: Total
A58: 1 | B58: Agriculture | C58: 1.737266e+11 | D58: 1.2537376e+12 | E58: =SUM(C58:D58) -> 1.4274642e+12
A59: 2 | B59: Societal Re-orientation | C59: 2.8735603e+11 | D59: 2.8936036e+11 | E59: =SUM(C59:D59) -> 5.7671639e+11
A60: 3 | B60: Poverty Alleviation | C60: 6.9074942e+10 | D60: 2.6331927e+11 | E60: =SUM(C60:D60) -> 3.3239422e+11
A61: 4 | B61: Health | C61: 1.2037867e+12 | D61: 2.1577388e+12 | E61: =SUM(C61:D61) -> 3.3615255e+12
A62: 5 | B62: Education | C62: 2.0200631e+12 | D62: 3.2789237e+12 | E62: =SUM(C62:D62) -> 5.2989868e+12
...

Sheet Population
A1: State | B1: 2024 Population | C1: 2025 Population
A2: ABIA | B2: 4373980.8 | C2: 4488922
A3: ADAMAWA | B3: 5183925.2 | C3: 5323995.9
A4: AKWA IBOM | B4: 5133482.6 | C4: 5207129.5
A5: ANAMBRA | B5: 6254054.6 | C5: 6393781.5
A6: BAUCHI | B6: 8868047.7 | C6: 9160342.6
A7: BAYELSA | B7: 2667078.7 | C7: 2725159.1
A8: BENUE | B8: 6416436.6 | C8: 6550152.3
A9: BORNO | B9: 6436142.9 | C9: 6582535.8
A10: CROSS RIVER | B10: 4600661 | C10: 4690861.1
A11: DELTA | B11: 5887050.9 | C11: 6010334.5
A12: EBONYI | B12: 3416070.9 | C12: 3504298.4
A13: EDO | B13: 5040581.2 | C13: 5165205.8
... A37: ZAMFARA | B37: 6184086.7 | C37: 6373594.1
A38: TOTAL: | B38: =SUM(B2:B37) -> 2.2540367e+08 | C38: =SUM(C2:C37) -> 2.3124155e+08

Sheet Population_23_Act_Total Exp
A1: State | B1: Population 2024 | C1: Actual Total Expenditure 2023
A2: ABIA | B2: 4373980.8 | C2: 1.4517256e+11
A3: ADAMAWA | B3: 5183925.2 | C3: 1.6196458e+11
A4: AKWA IBOM | B4: 5133482.6 | C4: 442227039000
A5: ANAMBRA | B5: 6254054.6 | C5: 1.62552e+11
A6: BAUCHI | B6: 8868047.7 | C6: 1.6047909e+11
A7: BAYELSA | B7: 2667078.7 | C7: 4.9234536e+11
A8: BENUE | B8: 6416436.6 | C8: 1.2126922e+11
A9: BORNO | B9: 6436142.9 | C9: 199592937267
A10: CROSS RIVER | B10: 4600661 | C10: 1.3643875e+11
A11: DELTA | B11: 5887050.9 | C11: 5.7950299e+11
A12: EBONYI | B12: 3416070.9 | C12: 1.3087182e+11
A13: EDO | B13: 5040581.2 | C13: 2.7238261e+11
... A37: ZAMFARA | B37: 6184086.7 | C37: 1.1899879e+11
A38: TOTAL: | B38: =SUM(B2:B37) -> 2.2540367e+08 | C38: =SUM(C2:C37) -> 9.3433619e+12
